<?xml version="1.0"?>
<robot name="wheel" 
       xmlns:xacro="http://www.ros.org/wiki/xacro">


<!--BU DOSYA ANA DOSYANIN İÇİNDE OLMALI! ORAYA INCLUDE EDİLECEK!!!!!-->


<!--PROPERTY LIST-->
<!-- pi sayısı -->
<xacro:property  name="M_PI" value="3.1415926535897931"/>  

 <!-- PI/2'NİN DEĞERİ RADYAN!!!!! -->
<xacro:property name="M_PI_2" value="1.57079632679"/>

<!-- 1 DERECE KAÇ RADYAN = 0.017 RADYAN -->
<xacro:property name="DEG_TO_RAD" value="0.0174533"/> 

<xacro:property name="wh_rad" value="0.04"/>
<xacro:property name="wh_height" value="0.02"/>
<xacro:property name="wh_mass" value="2.5"/>

<xacro:property name="base_x_origin_to_wheel_origin" value="0.25"/> <!-- 25 cm -->
<xacro:property name="base_y_origin_to_wheel_origin" value="0.3"/> <!-- 30 cm ÇAPIN TAMAMI-->
<xacro:property name="base_z_origin_to_wheel_origin" value="0.00"/> <!-- 0 cm -->

<!-- INERTIA MATRIX MACRO -->
<xacro:macro name="cylinder_inertia" params="m h r">
    <inertia ixx="${m*(h*h+3*r*r)/12}" ixy="0.0" ixz="0.0"
             iyy="${m*(h*h+3*r*r)/12}" iyz="0.0"
             izz="${m*r*r/2}"/>
</xacro:macro>



<!--WHEELS MACRO-->
<xacro:macro name="wheel" params="fb lr parent transX transY flipY">
    <link name="${fb}_${lr}_wheel">

        <inertial>
            <mass value="${wh_mass}"/>
            <origin xyz="0 0 0"/>
            <xacro:cylinder_inertia m="${wh_mass}" r="${wh_rad}" h="${wh_height}"/>
        </inertial>
        
        <visual>
            <origin xyz="0 0 0" rpy="${flipY*M_PI/2} 0 0"/> <!--90 derece dönsün, dik dursun tekerlek. baştta yatay geliyor çünkü.-->
            <geometry>
                <cylinder length="${wh_height}" radius="${wh_rad}"/>
            </geometry>
            <material name="black"/>
        </visual>

        <collision>
            <origin xyz="0 0 0" rpy="${flipY*M_PI/2} 0 0"/>
            <geometry>
                <cylinder length="${wh_height}" radius="${wh_rad}"/>
            </geometry>
        </collision>

    </link>


    <joint name="${fb}_${lr}_wheel_joint" type="continuous"> <!--ANA YAN TEKERLER CONTINUOUS!!!-->
        <parent link="${parent}"/>
        <child link="${fb}_${lr}_wheel"/>
        <origin xyz="${transX * base_x_origin_to_wheel_origin} ${transY * base_y_origin_to_wheel_origin} 0"/>
        <axis xyz="0 1 0" rpy="0 0 0"/> <!--TEKERLEKLER Y ETRAFINDA DÖNECEK-->
        <limit effort="100" velocity="100"/> <!--max 100 m/s-->
        <joint_properties damping="0.0" friction="0.0"/> <!-- eklemde bir sürtünme yok-->
    </joint>



</xacro:macro>


<!--yukarıdaki macro yu çağır: -->
<xacro:wheel fb="front" lr="right" parent="base_link" transX="0" transY="0.5" flipY="1"/>
<xacro:wheel fb="front" lr="left" parent="base_link" transX="0" transY="-0.5" flipY="1"/>




</robot>


